Workbook

Sheet 181
A1: HS8 México | B1: HS6 México | C1: Descripción HS6 | D1: Descripción HS8 | E1: LIGIE Julio | F1: LIGIE Septiembre | G1: LIGIE Diciembre
A2: 72107002 | B2: =LEFT(A2,6) -> 721070 | C2: =VLOOKUP(_xlfn.VALUETOTEXT($A2),LIGIE_Jul_25!$A$1:$E$8125,3,FALSE) -> Metales comunes y manufacturas de estos metales. Fundición, hierro y acero. Productos laminados planos de hierro o acero sin alear, de anchura superior o igual a 600 mm, chapados o revestidos. Pintados, barnizados o revestidos de plástico. | D2: =VLOOKUP(_xlfn.VALUETOTEXT($A2),LIGIE_Jul_25!$A$1:$E$8125,4,FALSE) -> Pintados, barnizados o revestidos de plástico. | E2: =VLOOKUP(_xlfn.VALUETOTEXT($A2),LIGIE_Jul_25!$A$1:$E$8125,5,FALSE) -> 25 | F2: =_xlfn.IFNA(VLOOKUP(_xlfn.VALUETOTEXT($A2),LIGIE_Iniciativa_Dec!$A$2:$E$1464,4,FALSE),"---") -> --- | G2: =_xlfn.IFNA(VLOOKUP(_xlfn.VALUETOTEXT($A2),LIGIE_Iniciativa_Dec!$A$2:$E$1464,5,FALSE),"---") -> ---
A3: 72124004 | B3: =LEFT(A3,6) -> 721240 | C3: =VLOOKUP(_xlfn.VALUETOTEXT($A3),LIGIE_Jul_25!$A$1:$E$8125,3,FALSE) -> Metales comunes y manufacturas de estos metales. Fundición, hierro y acero. Productos laminados planos de hierro o acero sin alear, de anchura inferior a 600 mm, chapados o revestidos. Pintados, barnizados o revestidos de plástico. | D3: =VLOOKUP(_xlfn.VALUETOTEXT($A3),LIGIE_Jul_25!$A$1:$E$8125,4,FALSE) -> Pintados, barnizados o revestidos de plástico. | E3: =VLOOKUP(_xlfn.VALUETOTEXT($A3),LIGIE_Jul_25!$A$1:$E$8125,5,FALSE) -> 25 | F3: =_xlfn.IFNA(VLOOKUP(_xlfn.VALUETOTEXT($A3),LIGIE_Iniciativa_Dec!$A$2:$E$1464,4,FALSE),"---") -> --- | G3: =_xlfn.IFNA(VLOOKUP(_xlfn.VALUETOTEXT($A3),LIGIE_Iniciativa_Dec!$A$2:$E$1464,5,FALSE),"---") -> ---
A4: 72166101 | B4: =LEFT(A4,6) -> 721661 | C4: =VLOOKUP(_xlfn.VALUETOTEXT($A4),LIGIE_Jul_25!$A$1:$E$8125,3,FALSE) -> Metales comunes y manufacturas de estos metales. Fundición, hierro y acero. Perfiles de hierro o acero sin alear. Perfiles simplemente obtenidos o acabados en frío: Obtenidos a partir de productos laminados planos. | D4: =VLOOKUP(_xlfn.VALUETOTEXT($A4),LIGIE_Jul_25!$A$1:$E$8125,4,FALSE) -> Perfiles en forma de H, I, L, T, U y Z, cuyo espesor no exceda a 23 cm, excepto lo comprendido en la fracción arancelaria 7216.61.02. | E4: =VLOOKUP(_xlfn.VALUETOTEXT($A4),LIGIE_Jul_25!$A$1:$E$8125,5,FALSE) -> 25 | F4: =_xlfn.IFNA(VLOOKUP(_xlfn.VALUETOTEXT($A4),LIGIE_Iniciativa_Dec!$A$2:$E$1464,4,FALSE),"---") -> --- | G4: =_xlfn.IFNA(VLOOKUP(_xlfn.VALUETOTEXT($A4),LIGIE_Iniciativa_Dec!$A$2:$E$1464,5,FALSE),"---") -> ---
A5: 72191101 | B5: =LEFT(A5,6) -> 721911 | C5: =VLOOKUP(_xlfn.VALUETOTEXT($A5),LIGIE_Jul_25!$A$1:$E$8125,3,FALSE) -> Metales comunes y manufacturas de estos metales. Fundición, hierro y acero. Productos laminados planos de acero inoxidable, de anchura superior o igual a 600 mm. Simplemente laminados en caliente, enrollados: De espesor superior a 10 mm. | D5: =VLOOKUP(_xlfn.VALUETOTEXT($A5),LIGIE_Jul_25!$A$1:$E$8125,4,FALSE) -> De espesor superior a 10 mm. | E5: =VLOOKUP(_xlfn.VALUETOTEXT($A5),LIGIE_Jul_25!$A$1:$E$8125,5,FALSE) -> Ex. | F5: =_xlfn.IFNA(VLOOKUP(_xlfn.VALUETOTEXT($A5),LIGIE_Iniciativa_Dec!$A$2:$E$1464,4,FALSE),"---") -> 20 | G5: =_xlfn.IFNA(VLOOKUP(_xlfn.VALUETOTEXT($A5),LIGIE_Iniciativa_Dec!$A$2:$E$1464,5,FALSE),"---") -> 20
A6: 72191202 | B6: =LEFT(A6,6) -> 721912 | C6: =VLOOKUP(_xlfn.VALUETOTEXT($A6),LIGIE_Jul_25!$A$1:$E$8125,3,FALSE) -> Metales comunes y manufacturas de estos metales. Fundición, hierro y acero. Productos laminados planos de acero inoxidable, de anchura superior o igual a 600 mm. Simplemente laminados en caliente, enrollados: De espesor superior o igual a 4.75 mm pero inferior o igual a 10 mm. | D6: =VLOOKUP(_xlfn.VALUETOTEXT($A6),LIGIE_Jul_25!$A$1:$E$8125,4,FALSE) -> De espesor superior o igual a 4.75 mm pero inferior o igual a 10 mm. | E6: =VLOOKUP(_xlfn.VALUETOTEXT($A6),LIGIE_Jul_25!$A$1:$E$8125,5,FALSE) -> Ex. | F6: =_xlfn.IFNA(VLOOKUP(_xlfn.VALUETOTEXT($A6),LIGIE_Iniciativa_Dec!$A$2:$E$1464,4,FALSE),"---") -> 20 | G6: =_xlfn.IFNA(VLOOKUP(_xlfn.VALUETOTEXT($A6),LIGIE_Iniciativa_Dec!$A$2:$E$1464,5,FALSE),"---") -> 20
A7: 72192101 | B7: =LEFT(A7,6) -> 721921 | C7: =VLOOKUP(_xlfn.VALUETOTEXT($A7),LIGIE_Jul_25!$A$1:$E$8125,3,FALSE) -> Metales comunes y manufacturas de estos metales. Fundición, hierro y acero. Productos laminados planos de acero inoxidable, de anchura superior o igual a 600 mm. Simplemente laminados en caliente, sin enrollar: De espesor superior a 10 mm. | D7: =VLOOKUP(_xlfn.VALUETOTEXT($A7),LIGIE_Jul_25!$A$1:$E$8125,4,FALSE) -> De espesor superior a 10 mm. | E7: =VLOOKUP(_xlfn.VALUETOTEXT($A7),LIGIE_Jul_25!$A$1:$E$8125,5,FALSE) -> Ex. | F7: =_xlfn.IFNA(VLOOKUP(_xlfn.VALUETOTEXT($A7),LIGIE_Iniciativa_Dec!$A$2:$E$1464,4,FALSE),"---") -> 20 | G7: =_xlfn.IFNA(VLOOKUP(_xlfn.VALUETOTEXT($A7),LIGIE_Iniciativa_Dec!$A$2:$E$1464,5,FALSE),"---") -> 20
A8: 72192201 | B8: =LEFT(A8,6) -> 721922 | C8: =VLOOKUP(_xlfn.VALUETOTEXT($A8),LIGIE_Jul_25!$A$1:$E$8125,3,FALSE) -> Metales comunes y manufacturas de estos metales. Fundición, hierro y acero. Productos laminados planos de acero inoxidable, de anchura superior o igual a 600 mm. Simplemente laminados en caliente, sin enrollar: De espesor superior o igual a 4.75 mm pero inferior o igual a 10 mm. | D8: =VLOOKUP(_xlfn.VALUETOTEXT($A8),LIGIE_Jul_25!$A$1:$E$8125,4,FALSE) -> De espesor superior o igual a 4.75 mm pero inferior o igual a 10 mm. | E8: =VLOOKUP(_xlfn.VALUETOTEXT($A8),LIGIE_Jul_25!$A$1:$E$8125,5,FALSE) -> Ex. | F8: =_xlfn.IFNA(VLOOKUP(_xlfn.VALUETOTEXT($A8),LIGIE_Iniciativa_Dec!$A$2:$E$1464,4,FALSE),"---") -> 20 | G8: =_xlfn.IFNA(VLOOKUP(_xlfn.VALUETOTEXT($A8),LIGIE_Iniciativa_Dec!$A$2:$E$1464,5,FALSE),"---") -> 20
A9: 72201101 | B9: =LEFT(A9,6) -> 722011 | C9: =VLOOKUP(_xlfn.VALUETOTEXT($A9),LIGIE_Jul_25!$A$1:$E$8125,3,FALSE) -> Metales comunes y manufacturas de estos metales. Fundición, hierro y acero. Productos laminados planos de acero inoxidable, de anchura inferior a 600 mm. Simplemente laminados en caliente: De espesor superior o igual a 4.75 mm. | D9: =VLOOKUP(_xlfn.VALUETOTEXT($A9),LIGIE_Jul_25!$A$1:$E$8125,4,FALSE) -> De espesor superior o igual a 4.75 mm. | E9: =VLOOKUP(_xlfn.VALUETOTEXT($A9),LIGIE_Jul_25!$A$1:$E$8125,5,FALSE) -> Ex. | F9: =_xlfn.IFNA(VLOOKUP(_xlfn.VALUETOTEXT($A9),LIGIE_Iniciativa_Dec!$A$2:$E$1464,4,FALSE),"---") -> 20 | G9: =_xlfn.IFNA(VLOOKUP(_xlfn.VALUETOTEXT($A9),LIGIE_Iniciativa_Dec!$A$2:$E$1464,5,FALSE),"---") -> 20
A10: 72201201 | B10: =LEFT(A10,6) -> 722012 | C10: =VLOOKUP(_xlfn.VALUETOTEXT($A10),LIGIE_Jul_25!$A$1:$E$8125,3,FALSE) -> Metales comunes y manufacturas de estos metales. Fundición, hierro y acero. Productos laminados planos de acero inoxidable, de anchura inferior a 600 mm. Simplemente laminados en caliente: De espesor inferior a 4.75 mm. | D10: =VLOOKUP(_xlfn.VALUETOTEXT($A10),LIGIE_Jul_25!$A$1:$E$8125,4,FALSE) -> De espesor inferior a 4.75 mm. | E10: =VLOOKUP(_xlfn.VALUETOTEXT($A10),LIGIE_Jul_25!$A$1:$E$8125,5,FALSE) -> Ex. | F10: =_xlfn.IFNA(VLOOKUP(_xlfn.VALUETOTEXT($A10),LIGIE_Iniciativa_Dec!$A$2:$E$1464,4,FALSE),"---") -> 20 | G10: =_xlfn.IFNA(VLOOKUP(_xlfn.VALUETOTEXT($A10),LIGIE_Iniciativa_Dec!$A$2:$E$1464,5,FALSE),"---") -> 20
A11: 72202003 | B11: =LEFT(A11,6) -> 722020 | C11: =VLOOKUP(_xlfn.VALUETOTEXT($A11),LIGIE_Jul_25!$A$1:$E$8125,3,FALSE) -> Metales comunes y manufacturas de estos metales. Fundición, hierro y acero. Productos laminados planos de acero inoxidable, de anchura inferior a 600 mm. Simplemente laminados en frío. | D11: =VLOOKUP(_xlfn.VALUETOTEXT($A11),LIGIE_Jul_25!$A$1:$E$8125,4,FALSE) -> Simplemente laminados en frío. | E11: =VLOOKUP(_xlfn.VALUETOTEXT($A11),LIGIE_Jul_25!$A$1:$E$8125,5,FALSE) -> 20 | F11: =_xlfn.IFNA(VLOOKUP(_xlfn.VALUETOTEXT($A11),LIGIE_Iniciativa_Dec!$A$2:$E$1464,4,FALSE),"---") -> 20 | G11: =_xlfn.IFNA(VLOOKUP(_xlfn.VALUETOTEXT($A11),LIGIE_Iniciativa_Dec!$A$2:$E$1464,5,FALSE),"---") -> 20
A12: 72251101 | B12: =LEFT(A12,6) -> 722511 | C12: =VLOOKUP(_xlfn.VALUETOTEXT($A12),LIGIE_Jul_25!$A$1:$E$8125,3,FALSE) -> Metales comunes y manufacturas de estos metales. Fundición, hierro y acero. Productos laminados planos de los demás aceros aleados, de anchura superior o igual a 600 mm. De acero al silicio llamado "magnético" (acero magnético al silicio): De grano orientado. | D12: =VLOOKUP(_xlfn.VALUETOTEXT($A12),LIGIE_Jul_25!$A$1:$E$8125,4,FALSE) -> De grano orientado. | E12: =VLOOKUP(_xlfn.VALUETOTEXT($A12),LIGIE_Jul_25!$A$1:$E$8125,5,FALSE) -> Ex. | F12: =_xlfn.IFNA(VLOOKUP(_xlfn.VALUETOTEXT($A12),LIGIE_Iniciativa_Dec!$A$2:$E$1464,4,FALSE),"---") -> --- | G12: =_xlfn.IFNA(VLOOKUP(_xlfn.VALUETOTEXT($A12),LIGIE_Iniciativa_Dec!$A$2:$E$1464,5,FALSE),"---") -> ---
A13: 72262001 | B13: =LEFT(A13,6) -> 722620 | C13: =VLOOKUP(_xlfn.VALUETOTEXT($A13),LIGIE_Jul_25!$A$1:$E$8125,3,FALSE) -> Metales comunes y manufacturas de estos metales. Fundición, hierro y acero. Productos laminados planos de los demás aceros aleados, de anchura inferior a 600 mm. De acero rápido. | D13: =VLOOKUP(_xlfn.VALUETOTEXT($A13),LIGIE_Jul_25!$A$1:$E$8125,4,FALSE) -> De acero rápido. | E13: =VLOOKUP(_xlfn.VALUETOTEXT($A13),LIGIE_Jul_25!$A$1:$E$8125,5,FALSE) -> Ex. | F13: =_xlfn.IFNA(VLOOKUP(_xlfn.VALUETOTEXT($A13),LIGIE_Iniciativa_Dec!$A$2:$E$1464,4,FALSE),"---") -> --- | G13: =_xlfn.IFNA(VLOOKUP(_xlfn.VALUETOTEXT($A13),LIGIE_Iniciativa_Dec!$A$2:$E$1464,5,FALSE),"---") -> Ex.
... A182: 90292006 | B182: =LEFT(A182,6) -> 902920 | C182: =VLOOKUP(_xlfn.VALUETOTEXT($A182),LIGIE_Jul_25!$A$1:$E$8125,3,FALSE) -> Instrumentos y aparatos de óptica, fotografía o cinematografía, de medida,. Instrumentos y aparatos de óptica, fotografía o cinematografía, de medida, control o precisión;. Los demás contadores (por ejemplo: cuentarrevoluciones, contadores de producción, taxímetros, cuentakilómetros, podómetros); velocímetros y tacómetros, excepto los de las partidas 90.14 o 90.15; estroboscopios. Velocímetros y tacómetros; estroboscopios. | D182: =VLOOKUP(_xlfn.VALUETOTEXT($A182),LIGIE_Jul_25!$A$1:$E$8125,4,FALSE) -> Velocímetros y tacómetros; estroboscopios. | E182: =VLOOKUP(_xlfn.VALUETOTEXT($A182),LIGIE_Jul_25!$A$1:$E$8125,5,FALSE) -> Ex. | F182: =_xlfn.IFNA(VLOOKUP(_xlfn.VALUETOTEXT($A182),LIGIE_Iniciativa_Dec!$A$2:$E$1464,4,FALSE),"---") -> 10 | G182: =_xlfn.IFNA(VLOOKUP(_xlfn.VALUETOTEXT($A182),LIGIE_Iniciativa_Dec!$A$2:$E$1464,5,FALSE),"---") -> 10

Sheet Secc_301
A1: 301 HS8 | B1: HS6 | C1: Descripción HS6 | D1: Descripción HS8 | E1: Arancel General | F1: Arancel 301
A2: 01012100 | B2: =LEFT(A2,6) -> 010121 | C2: =VLOOKUP($A2,HTS_Dec_25!$A$1:$E$11570,3,FALSE) -> Live animals; animal products. Live animals. Live horses, asses, mules and hinnies: Horses: | D2: =VLOOKUP($A2,HTS_Dec_25!$A$1:$E$11570,4,FALSE) -> Purebred breeding animals. | E2: =VLOOKUP($A2,HTS_Dec_25!$A$1:$E$11570,5,FALSE) -> Free | F2: 7.5
A3: 01012900 | B3: =LEFT(A3,6) -> 010129 | C3: =VLOOKUP($A3,HTS_Dec_25!$A$1:$E$11570,3,FALSE) -> Live animals; animal products. Live animals. Live horses, asses, mules and hinnies: Horses: | D3: =VLOOKUP($A3,HTS_Dec_25!$A$1:$E$11570,4,FALSE) -> Other. | E3: =VLOOKUP($A3,HTS_Dec_25!$A$1:$E$11570,5,FALSE) -> Free | F3: 7.5
A4: 01013000 | B4: =LEFT(A4,6) -> 010130 | C4: =VLOOKUP($A4,HTS_Dec_25!$A$1:$E$11570,3,FALSE) -> Live animals; animal products. Live animals. Live horses, asses, mules and hinnies: Asses | D4: =VLOOKUP($A4,HTS_Dec_25!$A$1:$E$11570,4,FALSE) -> Asses. | E4: =VLOOKUP($A4,HTS_Dec_25!$A$1:$E$11570,5,FALSE) -> 6.8% | F4: 7.5
A5: 01019030 | B5: =LEFT(A5,6) -> 010190 | C5: =VLOOKUP($A5,HTS_Dec_25!$A$1:$E$11570,3,FALSE) -> Live animals; animal products. Live animals. Live horses, asses, mules and hinnies: Other: | D5: =VLOOKUP($A5,HTS_Dec_25!$A$1:$E$11570,4,FALSE) -> Imported for immediate slaughter. | E5: =VLOOKUP($A5,HTS_Dec_25!$A$1:$E$11570,5,FALSE) -> Free | F5: 7.5
A6: 01019040 | B6: =LEFT(A6,6) -> 010190 | C6: =VLOOKUP($A6,HTS_Dec_25!$A$1:$E$11570,3,FALSE) -> Live animals; animal products. Live animals. Live horses, asses, mules and hinnies: Other: | D6: =VLOOKUP($A6,HTS_Dec_25!$A$1:$E$11570,4,FALSE) -> Other. | E6: =VLOOKUP($A6,HTS_Dec_25!$A$1:$E$11570,5,FALSE) -> 4.5% | F6: 7.5
A7: 01022100 | B7: =LEFT(A7,6) -> 010221 | C7: =VLOOKUP($A7,HTS_Dec_25!$A$1:$E$11570,3,FALSE) -> Live animals; animal products. Live animals. Live bovine animals: Cattle: | D7: =VLOOKUP($A7,HTS_Dec_25!$A$1:$E$11570,4,FALSE) -> Purebred breeding animals. | E7: =VLOOKUP($A7,HTS_Dec_25!$A$1:$E$11570,5,FALSE) -> Free | F7: 7.5
A8: 01022920 | B8: =LEFT(A8,6) -> 010229 | C8: =VLOOKUP($A8,HTS_Dec_25!$A$1:$E$11570,3,FALSE) -> Live animals; animal products. Live animals. Live bovine animals: Cattle: Other: | D8: =VLOOKUP($A8,HTS_Dec_25!$A$1:$E$11570,4,FALSE) -> Cows imported specially for dairy purposes. | E8: =VLOOKUP($A8,HTS_Dec_25!$A$1:$E$11570,5,FALSE) -> Free | F8: 7.5
A9: 01022940 | B9: =LEFT(A9,6) -> 010229 | C9: =VLOOKUP($A9,HTS_Dec_25!$A$1:$E$11570,3,FALSE) -> Live animals; animal products. Live animals. Live bovine animals: Cattle: Other: | D9: =VLOOKUP($A9,HTS_Dec_25!$A$1:$E$11570,4,FALSE) -> Other. | E9: =VLOOKUP($A9,HTS_Dec_25!$A$1:$E$11570,5,FALSE) -> 1¢/kg | F9: 7.5
A10: 01023100 | B10: =LEFT(A10,6) -> 010231 | C10: =VLOOKUP($A10,HTS_Dec_25!$A$1:$E$11570,3,FALSE) -> Live animals; animal products. Live animals. Live bovine animals: Buffalo: | D10: =VLOOKUP($A10,HTS_Dec_25!$A$1:$E$11570,4,FALSE) -> Purebred breeding animals. | E10: =VLOOKUP($A10,HTS_Dec_25!$A$1:$E$11570,5,FALSE) -> Free | F10: 7.5
A11: 01023900 | B11: =LEFT(A11,6) -> 010239 | C11: =VLOOKUP($A11,HTS_Dec_25!$A$1:$E$11570,3,FALSE) -> Live animals; animal products. Live animals. Live bovine animals: Buffalo: | D11: =VLOOKUP($A11,HTS_Dec_25!$A$1:$E$11570,4,FALSE) -> Other. | E11: =VLOOKUP($A11,HTS_Dec_25!$A$1:$E$11570,5,FALSE) -> 1¢/kg | F11: 7.5
A12: 01029000 | B12: =LEFT(A12,6) -> 010290 | C12: =VLOOKUP($A12,HTS_Dec_25!$A$1:$E$11570,3,FALSE) -> Live animals; animal products. Live animals. Live bovine animals: Other | D12: =VLOOKUP($A12,HTS_Dec_25!$A$1:$E$11570,4,FALSE) -> Other. | E12: =VLOOKUP($A12,HTS_Dec_25!$A$1:$E$11570,5,FALSE) -> 1¢/kg | F12: 7.5
A13: 01031000 | B13: =LEFT(A13,6) -> 010310 | C13: =VLOOKUP($A13,HTS_Dec_25!$A$1:$E$11570,3,FALSE) -> Live animals; animal products. Live animals. Live swine: Purebred breeding animals | D13: =VLOOKUP($A13,HTS_Dec_25!$A$1:$E$11570,4,FALSE) -> Purebred breeding animals. | E13: =VLOOKUP($A13,HTS_Dec_25!$A$1:$E$11570,5,FALSE) -> Free | F13: 7.5
... A10384: 97069000 | B10384: =LEFT(A10384,6) -> 970690 | C10384: =VLOOKUP($A10384,HTS_Dec_25!$A$1:$E$11570,3,FALSE) -> Works of art, collectors' pieces and antiques. Works of art, collectors' pieces and antiques. Antiques of an age exceeding 100 years: Other | D10384: =VLOOKUP($A10384,HTS_Dec_25!$A$1:$E$11570,4,FALSE) -> Other. | E10384: =VLOOKUP($A10384,HTS_Dec_25!$A$1:$E$11570,5,FALSE) -> Free | F10384: 7.5

Sheet HTS_Dec_25
A1: HS8 EUA | B1: HS6 EUA | C1: Descripción HS6 | D1: Descripción HS8 | E1: Arancel
A2: 01012100 | B2: =LEFT(A2,6) -> 010121 | C2: Live animals; animal products. Live animals. Live horses, asses, mules and hinnies: Horses: | D2: Purebred breeding animals. | E2: Free
A3: 01012900 | B3: =LEFT(A3,6) -> 010129 | C3: Live animals; animal products. Live animals. Live horses, asses, mules and hinnies: Horses: | D3: Other. | E3: Free
A4: 01013000 | B4: =LEFT(A4,6) -> 010130 | C4: Live animals; animal products. Live animals. Live horses, asses, mules and hinnies: Asses | D4: Asses. | E4: 6.8%
A5: 01019030 | B5: =LEFT(A5,6) -> 010190 | C5: Live animals; animal products. Live animals. Live horses, asses, mules and hinnies: Other: | D5: Imported for immediate slaughter. | E5: Free
A6: 01019040 | B6: =LEFT(A6,6) -> 010190 | C6: Live animals; animal products. Live animals. Live horses, asses, mules and hinnies: Other: | D6: Other. | E6: 4.5%
A7: 01022100 | B7: =LEFT(A7,6) -> 010221 | C7: Live animals; animal products. Live animals. Live bovine animals: Cattle: | D7: Purebred breeding animals. | E7: Free
A8: 01022920 | B8: =LEFT(A8,6) -> 010229 | C8: Live animals; animal products. Live animals. Live bovine animals: Cattle: Other: | D8: Cows imported specially for dairy purposes. | E8: Free
A9: 01022940 | B9: =LEFT(A9,6) -> 010229 | C9: Live animals; animal products. Live animals. Live bovine animals: Cattle: Other: | D9: Other. | E9: 1¢/kg
A10: 01023100 | B10: =LEFT(A10,6) -> 010231 | C10: Live animals; animal products. Live animals. Live bovine animals: Buffalo: | D10: Purebred breeding animals. | E10: Free
A11: 01023900 | B11: =LEFT(A11,6) -> 010239 | C11: Live animals; animal products. Live animals. Live bovine animals: Buffalo: | D11: Other. | E11: 1¢/kg
A12: 01029000 | B12: =LEFT(A12,6) -> 010290 | C12: Live animals; animal products. Live animals. Live bovine animals: Other | D12: Other. | E12: 1¢/kg
A13: 01031000 | B13: =LEFT(A13,6) -> 010310 | C13: Live animals; animal products. Live animals. Live swine: Purebred breeding animals | D13: Purebred breeding animals. | E13: Free
... A11570: 98220000 | B11570: =LEFT(A11570,6) -> 982200 | C11570: Special classification provisions; temporary legislation;temporary modifications established pursuant to trade legislation; additional import restrictions established pursuant to section 22 of the agricultural adjustment act, as amended. Special classification provisions. Textile or apparel goods of panama described in u.s. note 43 to this subchapter and entered pursuant to its provisions Goods provided for in subheadings 2207.10.60 or 2207.20.00: | D11570: Eligible apparel articles of chapter 62 assembled in the dominican republic and imported directly therefrom, under the terms of u.s. note 27 to this subchapter. | E11570: Free

Sheet LIGIE_Jul_25
A1: LIGIE Julio HS8 | B1: HS6 | C1: Descripción HS6 | D1: Descripción HS8 | E1: Arancel
A2: 01012101 | B2: 010121 | C2: Animales vivos y productos del reino animal. Animales vivos. Caballos, asnos, mulos y burdéganos, vivos. Caballos: Reproductores de raza pura. | D2: Reproductores de raza pura. | E2: 10
A3: 01012902 | B3: 010129 | C3: Animales vivos y productos del reino animal. Animales vivos. Caballos, asnos, mulos y burdéganos, vivos. Caballos: Los demás. | D3: Sin pedigree, para reproducción. | E3: 10
A4: 01012903 | B4: 010129 | C4: Animales vivos y productos del reino animal. Animales vivos. Caballos, asnos, mulos y burdéganos, vivos. Caballos: Los demás. | D4: Para abasto, cuando la importación la realicen empacadoras Tipo Inspección Federal. | E4: 10
A5: 01012999 | B5: 010129 | C5: Animales vivos y productos del reino animal. Animales vivos. Caballos, asnos, mulos y burdéganos, vivos. Caballos: Los demás. | D5: Los demás. | E5: 20
A6: 01013001 | B6: 010130 | C6: Animales vivos y productos del reino animal. Animales vivos. Caballos, asnos, mulos y burdéganos, vivos. Asnos. | D6: Asnos. | E6: 20
A7: 01019099 | B7: 010190 | C7: Animales vivos y productos del reino animal. Animales vivos. Caballos, asnos, mulos y burdéganos, vivos. Los demás. | D7: Los demás. | E7: 20
A8: 01022101 | B8: 010221 | C8: Animales vivos y productos del reino animal. Animales vivos. Animales vivos de la especie bovina. Bovinos domésticos: Reproductores de raza pura. | D8: Reproductores de raza pura. | E8: Ex.
A9: 01022901 | B9: 010229 | C9: Animales vivos y productos del reino animal. Animales vivos. Animales vivos de la especie bovina. Bovinos domésticos: Los demás. | D9: Vacas lecheras. | E9: Ex.
A10: 01022902 | B10: 010229 | C10: Animales vivos y productos del reino animal. Animales vivos. Animales vivos de la especie bovina. Bovinos domésticos: Los demás. | D10: Con pedigree o certificado de alto registro, excepto lo comprendido en la fracción arancelaria 0102.29.01. | E10: Ex.
A11: 01022999 | B11: 010229 | C11: Animales vivos y productos del reino animal. Animales vivos. Animales vivos de la especie bovina. Bovinos domésticos: Los demás. | D11: Los demás. | E11: 15
A12: 01023101 | B12: 010231 | C12: Animales vivos y productos del reino animal. Animales vivos. Animales vivos de la especie bovina. Búfalos: Reproductores de raza pura. | D12: Reproductores de raza pura. | E12: Ex.
... A4224: 60052401 | B4224: 600524 | C4224: Materias textiles y sus manufacturas. Tejidos de punto. Tejidos de punto por urdimbre (incluidos los obtenidos en telares de pasamanería), excepto los de las partidas 60.01 a 60.04. De algodón: Estampados. | D4224: Estampados. | E4224: 10
A4225: 60053501 | B4225: 600535 | C4225: Materias textiles y sus manufacturas. Tejidos de punto. Tejidos de punto por urdimbre (incluidos los obtenidos en telares de pasamanería), excepto los de las partidas 60.01 a 60.04. De fibras sintéticas: Tejidos mencionados en la Nota 1 de subpartida de este Capítulo. | D4225: Tejidos mencionados en la Nota 1 de subpartida de este Capítulo. | E4225: 10
A4226: 60053691 | B4226: 600536 | C4226: Materias textiles y sus manufacturas. Tejidos de punto. Tejidos de punto por urdimbre (incluidos los obtenidos en telares de pasamanería), excepto los de las partidas 60.01 a 60.04. De fibras sintéticas: Los demás, crudos o blanqueados. | D4226: Los demás, crudos o blanqueados. | E4226: 10
A4227: 60053791 | B4227: 600537 | C4227: Materias textiles y sus manufacturas. Tejidos de punto. Tejidos de punto por urdimbre (incluidos los obtenidos en telares de pasamanería), excepto los de las partidas 60.01 a 60.04. De fibras sintéticas: Los demás, teñidos. | D4227: Los demás, teñidos. | E4227: 15
A4228: 60053891 | B4228: 600538 | C4228: Materias textiles y sus manufacturas. Tejidos de punto. Tejidos de punto por urdimbre (incluidos los obtenidos en telares de pasamanería), excepto los de las partidas 60.01 a 60.04. De fibras sintéticas: Los demás, con hilados de distintos colores. | D4228: Los demás, con hilados de distintos colores. | E4228: 10
A4229: 60053991 | B4229: 600539 | C4229: Materias textiles y sus manufacturas. Tejidos de punto. Tejidos de punto por urdimbre (incluidos los obtenidos en telares de pasamanería), excepto los de las partidas 60.01 a 60.04. De fibras sintéticas: Los demás, estampados. | D4229: Los demás, estampados. | E4229: 10
A4230: 60054101 | B4230: 600541 | C4230: Materias textiles y sus manufacturas. Tejidos de punto. Tejidos de punto por urdimbre (incluidos los obtenidos en telares de pasamanería), excepto los de las partidas 60.01 a 60.04. De fibras artificiales: Crudos o blanqueados. | D4230: Crudos o blanqueados. | E4230: 10
A4231: 60054201 | B4231: 600542 | C4231: Materias textiles y sus manufacturas. Tejidos de punto. Tejidos de punto por urdimbre (incluidos los obtenidos en telares de pasamanería), excepto los de las partidas 60.01 a 60.04. De fibras artificiales: Teñidos. | D4231: Teñidos. | E4231: 10
A4232: 60054301 | B4232: 600543 | C4232: Materias textiles y sus manufacturas. Tejidos de punto. Tejidos de punto por urdimbre (incluidos los obtenidos en telares de pasamanería), excepto los de las partidas 60.01 a 60.04. De fibras artificiales: Con hilados de distintos colores. | D4232: Con hilados de distintos colores. | E4232: 10
A4233: 60054401 | B4233: 600544 | C4233: Materias textiles y sus manufacturas. Tejidos de punto. Tejidos de punto por urdimbre (incluidos los obtenidos en telares de pasamanería), excepto los de las partidas 60.01 a 60.04. De fibras artificiales: Estampados. | D4233: Estampados. | E4233: 10
A4234: 60059099 | B4234: 600590 | C4234: Materias textiles y sus manufacturas. Tejidos de punto. Tejidos de punto por urdimbre (incluidos los obtenidos en telares de pasamanería), excepto los de las partidas 60.01 a 60.04. Los demás. | D4234: Los demás. | E4234: 10
A4235: 60061001 | B4235: 600610 | C4235: Materias textiles y sus manufacturas. Tejidos de punto. Los demás tejidos de punto. De lana o pelo fino. | D4235: De lana o pelo fino. | E4235: 10
A4236: 60062102 | B4236: 600621 | C4236: Materias textiles y sus manufacturas. Tejidos de punto. Los demás tejidos de punto. De algodón: Crudos o blanqueados. | D4236: Crudos o blanqueados. | E4236: 10
A4237: 60062202 | B4237: 600622 | C4237: Materias textiles y sus manufacturas. Tejidos de punto. Los demás tejidos de punto. De algodón: Teñidos. | D4237: Teñidos. | E4237: 15
... A4425: 62045301 | B4425: 620453 | C4425: Materias textiles y sus manufacturas. Prendas y complementos (accesorios), de vestir, excepto los de punto. Trajes sastre, conjuntos, chaquetas (sacos), vestidos, faldas, faldas pantalón, pantalones largos, pantalones con peto, pantalones cortos (calzones) y shorts (excepto de baño), para mujeres o niñas. Faldas y faldas pantalón: De fibras sintéticas. | D4425: Hechas totalmente a mano. | E4425: 20
A4426: 62045302 | B4426: 620453 | C4426: Materias textiles y sus manufacturas. Prendas y complementos (accesorios), de vestir, excepto los de punto. Trajes sastre, conjuntos, chaquetas (sacos), vestidos, faldas, faldas pantalón, pantalones largos, pantalones con peto, pantalones cortos (calzones) y shorts (excepto de baño), para mujeres o niñas. Faldas y faldas pantalón: De fibras sintéticas. | D4426: Con un contenido de lana o pelo fino superior o igual a 36% en peso, excepto lo comprendido en la fracción arancelaria 6204.53.01. | E4426: 20
A4427: 62045399 | B4427: 620453 | C4427: Materias textiles y sus manufacturas. Prendas y complementos (accesorios), de vestir, excepto los de punto. Trajes sastre, conjuntos, chaquetas (sacos), vestidos, faldas, faldas pantalón, pantalones largos, pantalones con peto, pantalones cortos (calzones) y shorts (excepto de baño), para mujeres o niñas. Faldas y faldas pantalón: De fibras sintéticas. | D4427: Los demás. | E4427: 35
A4428: 62045991 | B4428: 620459 | C4428: Materias textiles y sus manufacturas. Prendas y complementos (accesorios), de vestir, excepto los de punto. Trajes sastre, conjuntos, chaquetas (sacos), vestidos, faldas, faldas pantalón, pantalones largos, pantalones con peto, pantalones cortos (calzones) y shorts (excepto de baño), para mujeres o niñas. Faldas y faldas pantalón: De las demás materias textiles. | D4428: De las demás materias textiles. | E4428: 35 | H4428: =_xlfn.VALUETOTEXT(LEFT(A4428,6)) -> 620459
A4429: 62046101 | B4429: 620461 | C4429: Materias textiles y sus manufacturas. Prendas y complementos (accesorios), de vestir, excepto los de punto. Trajes sastre, conjuntos, chaquetas (sacos), vestidos, faldas, faldas pantalón, pantalones largos, pantalones con peto, pantalones cortos (calzones) y shorts (excepto de baño), para mujeres o niñas. Pantalones largos, pantalones con peto, pantalones cortos (calzones) y shorts: De lana o pelo fino. | D4429: De lana o pelo fino. | E4429: 20
A4430: 62046209 | B4430: 620462 | C4430: Materias textiles y sus manufacturas. Prendas y complementos (accesorios), de vestir, excepto los de punto. Trajes sastre, conjuntos, chaquetas (sacos), vestidos, faldas, faldas pantalón, pantalones largos, pantalones con peto, pantalones cortos (calzones) y shorts (excepto de baño), para mujeres o niñas. Pantalones largos, pantalones con peto, pantalones cortos (calzones) y shorts: De algodón. | D4430: De algodón. | E4430: 35
A4431: 62046301 | B4431: 620463 | C4431: Materias textiles y sus manufacturas. Prendas y complementos (accesorios), de vestir, excepto los de punto. Trajes sastre, conjuntos, chaquetas (sacos), vestidos, faldas, faldas pantalón, pantalones largos, pantalones con peto, pantalones cortos (calzones) y shorts (excepto de baño), para mujeres o niñas. Pantalones largos, pantalones con peto, pantalones cortos (calzones) y shorts: De fibras sintéticas. | D4431: Con un contenido de lana o pelo fino superior o igual a 36% en peso. | E4431: 20
A4432: 62046391 | B4432: 620463 | C4432: Materias textiles y sus manufacturas. Prendas y complementos (accesorios), de vestir, excepto los de punto. Trajes sastre, conjuntos, chaquetas (sacos), vestidos, faldas, faldas pantalón, pantalones largos, pantalones con peto, pantalones cortos (calzones) y shorts (excepto de baño), para mujeres o niñas. Pantalones largos, pantalones con peto, pantalones cortos (calzones) y shorts: De fibras sintéticas. | D4432: Los demás, para mujeres. | E4432: 35
A4433: 62046392 | B4433: 620463 | C4433: Materias textiles y sus manufacturas. Prendas y complementos (accesorios), de vestir, excepto los de punto. Trajes sastre, conjuntos, chaquetas (sacos), vestidos, faldas, faldas pantalón, pantalones largos, pantalones con peto, pantalones cortos (calzones) y shorts (excepto de baño), para mujeres o niñas. Pantalones largos, pantalones con peto, pantalones cortos (calzones) y shorts: De fibras sintéticas. | D4433: Los demás, para niñas. | E4433: 35
A4434: 62046902 | B4434: 620469 | C4434: Materias textiles y sus manufacturas. Prendas y complementos (accesorios), de vestir, excepto los de punto. Trajes sastre, conjuntos, chaquetas (sacos), vestidos, faldas, faldas pantalón, pantalones largos, pantalones con peto, pantalones cortos (calzones) y shorts (excepto de baño), para mujeres o niñas. Pantalones largos, pantalones con peto, pantalones cortos (calzones) y shorts: De las demás materias textiles. | D4434: Con un contenido de seda superior o igual a 70% en peso. | E4434: 20
A4435: 62046903 | B4435: 620469 | C4435: Materias textiles y sus manufacturas. Prendas y complementos (accesorios), de vestir, excepto los de punto. Trajes sastre, conjuntos, chaquetas (sacos), vestidos, faldas, faldas pantalón, pantalones largos, pantalones con peto, pantalones cortos (calzones) y shorts (excepto de baño), para mujeres o niñas. Pantalones largos, pantalones con peto, pantalones cortos (calzones) y shorts: De las demás materias textiles. | D4435: Con un contenido de lana o pelo fino superior o igual a 36% en peso. | E4435: 20
A4436: 62046999 | B4436: 620469 | C4436: Materias textiles y sus manufacturas. Prendas y complementos (accesorios), de vestir, excepto los de punto. Trajes sastre, conjuntos, chaquetas (sacos), vestidos, faldas, faldas pantalón, pantalones largos, pantalones con peto, pantalones cortos (calzones) y shorts (excepto de baño), para mujeres o niñas. Pantalones largos, pantalones con peto, pantalones cortos (calzones) y shorts: De las demás materias textiles. | D4436: Los demás. | E4436: 35
A4437: 62052001 | B4437: 620520 | C4437: Materias textiles y sus manufacturas. Prendas y complementos (accesorios), de vestir, excepto los de punto. Camisas para hombres o niños. De algodón. | D4437: Hechas totalmente a mano. | E4437: 20
A4438: 62052091 | B4438: 620520 | C4438: Materias textiles y sus manufacturas. Prendas y complementos (accesorios), de vestir, excepto los de punto. Camisas para hombres o niños. De algodón. | D4438: Para hombres, excepto lo comprendido en la fracción arancelaria 6205.20.01. | E4438: 35
...

Sheet Iniciativa
A1: LIGIE Iniciativa HS8 | B1: HS6 | C1: Descripción HS6 | D1: Descripción HS8 | E1: Septiembre | F1: Diciembre
A2: 33030001 | B2: =LEFT(A2,6) -> 330300 | C2: =VLOOKUP(_xlfn.VALUETOTEXT($A2),LIGIE_Jul_25!$A$2:$E$8125,3,FALSE) -> Productos de las industrias químicas o de las industrias conexas. Aceites esenciales y resinoides; preparaciones de perfumería, de tocador o de cosmética. Perfumes y aguas de tocador. Perfumes y aguas de tocador. | D2: =VLOOKUP(_xlfn.VALUETOTEXT($A2),LIGIE_Jul_25!$A$2:$E$8125,4,FALSE) -> Aguas de tocador. | E2: =_xlfn.IFNA(VLOOKUP(_xlfn.VALUETOTEXT($A2),LIGIE_Iniciativa_Dec!$A$2:$E$1464,4,FALSE),"---") -> 35 | F2: =_xlfn.IFNA(VLOOKUP(_xlfn.VALUETOTEXT($A2),LIGIE_Iniciativa_Dec!$A$2:$E$1464,4,FALSE),"---") -> 35
A3: 33030099 | B3: =LEFT(A3,6) -> 330300 | C3: =VLOOKUP(_xlfn.VALUETOTEXT($A3),LIGIE_Jul_25!$A$2:$E$8125,3,FALSE) -> Productos de las industrias químicas o de las industrias conexas. Aceites esenciales y resinoides; preparaciones de perfumería, de tocador o de cosmética. Perfumes y aguas de tocador. Perfumes y aguas de tocador. | D3: =VLOOKUP(_xlfn.VALUETOTEXT($A3),LIGIE_Jul_25!$A$2:$E$8125,4,FALSE) -> Los demás. | E3: =_xlfn.IFNA(VLOOKUP(_xlfn.VALUETOTEXT($A3),LIGIE_Iniciativa_Dec!$A$2:$E$1464,4,FALSE),"---") -> 35 | F3: =_xlfn.IFNA(VLOOKUP(_xlfn.VALUETOTEXT($A3),LIGIE_Iniciativa_Dec!$A$2:$E$1464,4,FALSE),"---") -> 35
A4: 33041001 | B4: =LEFT(A4,6) -> 330410 | C4: =VLOOKUP(_xlfn.VALUETOTEXT($A4),LIGIE_Jul_25!$A$2:$E$8125,3,FALSE) -> Productos de las industrias químicas o de las industrias conexas. Aceites esenciales y resinoides; preparaciones de perfumería, de tocador o de cosmética. Preparaciones de belleza, maquillaje y para el cuidado de la piel, excepto los medicamentos, incluidas las preparaciones antisolares y las bronceadoras; preparaciones para manicuras o pedicuros. Preparaciones para el maquillaje de los labios. | D4: =VLOOKUP(_xlfn.VALUETOTEXT($A4),LIGIE_Jul_25!$A$2:$E$8125,4,FALSE) -> Preparaciones para el maquillaje de los labios. | E4: =_xlfn.IFNA(VLOOKUP(_xlfn.VALUETOTEXT($A4),LIGIE_Iniciativa_Dec!$A$2:$E$1464,4,FALSE),"---") -> 50 | F4: =_xlfn.IFNA(VLOOKUP(_xlfn.VALUETOTEXT($A4),LIGIE_Iniciativa_Dec!$A$2:$E$1464,4,FALSE),"---") -> 50
A5: 33042001 | B5: =LEFT(A5,6) -> 330420 | C5: =VLOOKUP(_xlfn.VALUETOTEXT($A5),LIGIE_Jul_25!$A$2:$E$8125,3,FALSE) -> Productos de las industrias químicas o de las industrias conexas. Aceites esenciales y resinoides; preparaciones de perfumería, de tocador o de cosmética. Preparaciones de belleza, maquillaje y para el cuidado de la piel, excepto los medicamentos, incluidas las preparaciones antisolares y las bronceadoras; preparaciones para manicuras o pedicuros. Preparaciones para el maquillaje de los ojos. | D5: =VLOOKUP(_xlfn.VALUETOTEXT($A5),LIGIE_Jul_25!$A$2:$E$8125,4,FALSE) -> Preparaciones para el maquillaje de los ojos. | E5: =_xlfn.IFNA(VLOOKUP(_xlfn.VALUETOTEXT($A5),LIGIE_Iniciativa_Dec!$A$2:$E$1464,4,FALSE),"---") -> 35 | F5: =_xlfn.IFNA(VLOOKUP(_xlfn.VALUETOTEXT($A5),LIGIE_Iniciativa_Dec!$A$2:$E$1464,4,FALSE),"---") -> 35
A6: 33043001 | B6: =LEFT(A6,6) -> 330430 | C6: =VLOOKUP(_xlfn.VALUETOTEXT($A6),LIGIE_Jul_25!$A$2:$E$8125,3,FALSE) -> Productos de las industrias químicas o de las industrias conexas. Aceites esenciales y resinoides; preparaciones de perfumería, de tocador o de cosmética. Preparaciones de belleza, maquillaje y para el cuidado de la piel, excepto los medicamentos, incluidas las preparaciones antisolares y las bronceadoras; preparaciones para manicuras o pedicuros. Preparaciones para manicuras o pedicuros. | D6: =VLOOKUP(_xlfn.VALUETOTEXT($A6),LIGIE_Jul_25!$A$2:$E$8125,4,FALSE) -> Preparaciones para manicuras o pedicuros. | E6: =_xlfn.IFNA(VLOOKUP(_xlfn.VALUETOTEXT($A6),LIGIE_Iniciativa_Dec!$A$2:$E$1464,4,FALSE),"---") -> 35 | F6: =_xlfn.IFNA(VLOOKUP(_xlfn.VALUETOTEXT($A6),LIGIE_Iniciativa_Dec!$A$2:$E$1464,4,FALSE),"---") -> 35
A7: 33049101 | B7: =LEFT(A7,6) -> 330491 | C7: =VLOOKUP(_xlfn.VALUETOTEXT($A7),LIGIE_Jul_25!$A$2:$E$8125,3,FALSE) -> Productos de las industrias químicas o de las industrias conexas. Aceites esenciales y resinoides; preparaciones de perfumería, de tocador o de cosmética. Preparaciones de belleza, maquillaje y para el cuidado de la piel, excepto los medicamentos, incluidas las preparaciones antisolares y las bronceadoras; preparaciones para manicuras o pedicuros. Las demás: Polvos, incluidos los compactos. | D7: =VLOOKUP(_xlfn.VALUETOTEXT($A7),LIGIE_Jul_25!$A$2:$E$8125,4,FALSE) -> Polvos, incluidos los compactos. | E7: =_xlfn.IFNA(VLOOKUP(_xlfn.VALUETOTEXT($A7),LIGIE_Iniciativa_Dec!$A$2:$E$1464,4,FALSE),"---") -> 35 | F7: =_xlfn.IFNA(VLOOKUP(_xlfn.VALUETOTEXT($A7),LIGIE_Iniciativa_Dec!$A$2:$E$1464,4,FALSE),"---") -> 35
A8: 33049901 | B8: =LEFT(A8,6) -> 330499 | C8: =VLOOKUP(_xlfn.VALUETOTEXT($A8),LIGIE_Jul_25!$A$2:$E$8125,3,FALSE) -> Productos de las industrias químicas o de las industrias conexas. Aceites esenciales y resinoides; preparaciones de perfumería, de tocador o de cosmética. Preparaciones de belleza, maquillaje y para el cuidado de la piel, excepto los medicamentos, incluidas las preparaciones antisolares y las bronceadoras; preparaciones para manicuras o pedicuros. Las demás: Las demás. | D8: =VLOOKUP(_xlfn.VALUETOTEXT($A8),LIGIE_Jul_25!$A$2:$E$8125,4,FALSE) -> Leches cutáneas. | E8: =_xlfn.IFNA(VLOOKUP(_xlfn.VALUETOTEXT($A8),LIGIE_Iniciativa_Dec!$A$2:$E$1464,4,FALSE),"---") -> 35 | F8: =_xlfn.IFNA(VLOOKUP(_xlfn.VALUETOTEXT($A8),LIGIE_Iniciativa_Dec!$A$2:$E$1464,4,FALSE),"---") -> 35
A9: 33049999 | B9: =LEFT(A9,6) -> 330499 | C9: =VLOOKUP(_xlfn.VALUETOTEXT($A9),LIGIE_Jul_25!$A$2:$E$8125,3,FALSE) -> Productos de las industrias químicas o de las industrias conexas. Aceites esenciales y resinoides; preparaciones de perfumería, de tocador o de cosmética. Preparaciones de belleza, maquillaje y para el cuidado de la piel, excepto los medicamentos, incluidas las preparaciones antisolares y las bronceadoras; preparaciones para manicuras o pedicuros. Las demás: Las demás. | D9: =VLOOKUP(_xlfn.VALUETOTEXT($A9),LIGIE_Jul_25!$A$2:$E$8125,4,FALSE) -> Las demás. | E9: =_xlfn.IFNA(VLOOKUP(_xlfn.VALUETOTEXT($A9),LIGIE_Iniciativa_Dec!$A$2:$E$1464,4,FALSE),"---") -> 35 | F9: =_xlfn.IFNA(VLOOKUP(_xlfn.VALUETOTEXT($A9),LIGIE_Iniciativa_Dec!$A$2:$E$1464,4,FALSE),"---") -> 35
A10: 33051001 | B10: =LEFT(A10,6) -> 330510 | C10: =VLOOKUP(_xlfn.VALUETOTEXT($A10),LIGIE_Jul_25!$A$2:$E$8125,3,FALSE) -> Productos de las industrias químicas o de las industrias conexas. Aceites esenciales y resinoides; preparaciones de perfumería, de tocador o de cosmética. Preparaciones capilares. Champúes. | D10: =VLOOKUP(_xlfn.VALUETOTEXT($A10),LIGIE_Jul_25!$A$2:$E$8125,4,FALSE) -> Champúes. | E10: =_xlfn.IFNA(VLOOKUP(_xlfn.VALUETOTEXT($A10),LIGIE_Iniciativa_Dec!$A$2:$E$1464,4,FALSE),"---") -> 35 | F10: =_xlfn.IFNA(VLOOKUP(_xlfn.VALUETOTEXT($A10),LIGIE_Iniciativa_Dec!$A$2:$E$1464,4,FALSE),"---") -> 35
A11: 33052001 | B11: =LEFT(A11,6) -> 330520 | C11: =VLOOKUP(_xlfn.VALUETOTEXT($A11),LIGIE_Jul_25!$A$2:$E$8125,3,FALSE) -> Productos de las industrias químicas o de las industrias conexas. Aceites esenciales y resinoides; preparaciones de perfumería, de tocador o de cosmética. Preparaciones capilares. Preparaciones para ondulación o desrizado permanentes. | D11: =VLOOKUP(_xlfn.VALUETOTEXT($A11),LIGIE_Jul_25!$A$2:$E$8125,4,FALSE) -> Preparaciones para ondulación o desrizado permanentes. | E11: =_xlfn.IFNA(VLOOKUP(_xlfn.VALUETOTEXT($A11),LIGIE_Iniciativa_Dec!$A$2:$E$1464,4,FALSE),"---") -> 35 | F11: =_xlfn.IFNA(VLOOKUP(_xlfn.VALUETOTEXT($A11),LIGIE_Iniciativa_Dec!$A$2:$E$1464,4,FALSE),"---") -> 35
A12: 33053001 | B12: =LEFT(A12,6) -> 330530 | C12: =VLOOKUP(_xlfn.VALUETOTEXT($A12),LIGIE_Jul_25!$A$2:$E$8125,3,FALSE) -> Productos de las industrias químicas o de las industrias conexas. Aceites esenciales y resinoides; preparaciones de perfumería, de tocador o de cosmética. Preparaciones capilares. Lacas para el cabello. | D12: =VLOOKUP(_xlfn.VALUETOTEXT($A12),LIGIE_Jul_25!$A$2:$E$8125,4,FALSE) -> Lacas para el cabello. | E12: =_xlfn.IFNA(VLOOKUP(_xlfn.VALUETOTEXT($A12),LIGIE_Iniciativa_Dec!$A$2:$E$1464,4,FALSE),"---") -> 35 | F12: =_xlfn.IFNA(VLOOKUP(_xlfn.VALUETOTEXT($A12),LIGIE_Iniciativa_Dec!$A$2:$E$1464,4,FALSE),"---") -> 35
A13: 33059099 | B13: =LEFT(A13,6) -> 330590 | C13: =VLOOKUP(_xlfn.VALUETOTEXT($A13),LIGIE_Jul_25!$A$2:$E$8125,3,FALSE) -> Productos de las industrias químicas o de las industrias conexas. Aceites esenciales y resinoides; preparaciones de perfumería, de tocador o de cosmética. Preparaciones capilares. Las demás. | D13: =VLOOKUP(_xlfn.VALUETOTEXT($A13),LIGIE_Jul_25!$A$2:$E$8125,4,FALSE) -> Las demás. | E13: =_xlfn.IFNA(VLOOKUP(_xlfn.VALUETOTEXT($A13),LIGIE_Iniciativa_Dec!$A$2:$E$1464,4,FALSE),"---") -> 35 | F13: =_xlfn.IFNA(VLOOKUP(_xlfn.VALUETOTEXT($A13),LIGIE_Iniciativa_Dec!$A$2:$E$1464,4,FALSE),"---") -> 35
... A1574: 95069906 | B1574: =LEFT(A1574,6) -> 950699 | C1574: =VLOOKUP(_xlfn.VALUETOTEXT($A1574),LIGIE_Jul_25!$A$2:$E$8125,3,FALSE) -> Mercancías y productos diversos. Juguetes, juegos y artículos para recreo o deporte; sus partes y accesorios. Artículos y material para cultura física, gimnasia, atletismo, demás deportes (incluido el tenis de mesa) o para juegos al aire libre, no expresados ni comprendidos en otra parte de este Capítulo; piscinas, incluso infantiles. Los demás: Los demás. | D1574: =VLOOKUP(_xlfn.VALUETOTEXT($A1574),LIGIE_Jul_25!$A$2:$E$8125,4,FALSE) -> Piscinas, incluso infantiles. | E1574: =_xlfn.IFNA(VLOOKUP(_xlfn.VALUETOTEXT($A1574),LIGIE_Iniciativa_Dec!$A$2:$E$1464,4,FALSE),"---") -> --- | F1574: =_xlfn.IFNA(VLOOKUP(_xlfn.VALUETOTEXT($A1574),LIGIE_Iniciativa_Dec!$A$2:$E$1464,4,FALSE),"---") -> ---
A1575: 55131201 | B1575: =LEFT(A1575,6) -> 551312 | C1575: =VLOOKUP(_xlfn.VALUETOTEXT($A1575),LIGIE_Jul_25!$A$2:$E$8125,3,FALSE) -> Materias textiles y sus manufacturas. Fibras sintéticas o artificiales discontinuas. Tejidos de fibras sintéticas discontinuas con un contenido de estas fibras inferior al 85% en peso, mezcladas exclusiva o principalmente con algodón, de peso inferior o igual a 170 g/m². Crudos o blanqueados: De fibras discontinuas de poliéster, de ligamento sarga, incluido el cruzado, de curso inferior o igual a 4. | D1575: =VLOOKUP(_xlfn.VALUETOTEXT($A1575),LIGIE_Jul_25!$A$2:$E$8125,4,FALSE) -> De fibras discontinuas de poliéster, de ligamento sarga, incluido el cruzado, de curso inferior o igual a 4. | E1575: =_xlfn.IFNA(VLOOKUP(_xlfn.VALUETOTEXT($A1575),LIGIE_Iniciativa_Dec!$A$2:$E$1464,4,FALSE),"---") -> 35 | F1575: =_xlfn.IFNA(VLOOKUP(_xlfn.VALUETOTEXT($A1575),LIGIE_Iniciativa_Dec!$A$2:$E$1464,4,FALSE),"---") -> 35
A1576: 96138099 | B1576: =LEFT(A1576,6) -> 961380 | C1576: =VLOOKUP(_xlfn.VALUETOTEXT($A1576),LIGIE_Jul_25!$A$2:$E$8125,3,FALSE) -> Mercancías y productos diversos. Manufacturas diversas. Encendedores y mecheros, incluso mecánicos o eléctricos, y sus partes, excepto las piedras y mechas. Los demás encendedores y mecheros. | D1576: =VLOOKUP(_xlfn.VALUETOTEXT($A1576),LIGIE_Jul_25!$A$2:$E$8125,4,FALSE) -> Los demás. | E1576: =_xlfn.IFNA(VLOOKUP(_xlfn.VALUETOTEXT($A1576),LIGIE_Iniciativa_Dec!$A$2:$E$1464,4,FALSE),"---") -> --- | F1576: =_xlfn.IFNA(VLOOKUP(_xlfn.VALUETOTEXT($A1576),LIGIE_Iniciativa_Dec!$A$2:$E$1464,4,FALSE),"---") -> ---
A1577: 96139001 | B1577: =LEFT(A1577,6) -> 961390 | C1577: =VLOOKUP(_xlfn.VALUETOTEXT($A1577),LIGIE_Jul_25!$A$2:$E$8125,3,FALSE) -> Mercancías y productos diversos. Manufacturas diversas. Encendedores y mecheros, incluso mecánicos o eléctricos, y sus partes, excepto las piedras y mechas. Partes. | D1577: =VLOOKUP(_xlfn.VALUETOTEXT($A1577),LIGIE_Jul_25!$A$2:$E$8125,4,FALSE) -> Reconocibles como diseñadas exclusivamente para los encendedores de cigarrillos a base de resistencia para uso automotriz. | E1577: =_xlfn.IFNA(VLOOKUP(_xlfn.VALUETOTEXT($A1577),LIGIE_Iniciativa_Dec!$A$2:$E$1464,4,FALSE),"---") -> 35 | F1577: =_xlfn.IFNA(VLOOKUP(_xlfn.VALUETOTEXT($A1577),LIGIE_Iniciativa_Dec!$A$2:$E$1464,4,FALSE),"---") -> 35
A1578: 96190001 | B1578: =LEFT(A1578,6) -> 961900 | C1578: =VLOOKUP(_xlfn.VALUETOTEXT($A1578),LIGIE_Jul_25!$A$2:$E$8125,3,FALSE) -> Mercancías y productos diversos. Manufacturas diversas. Compresas y tampones higiénicos, pañales y artículos similares, de cualquier materia. Compresas y tampones higiénicos, pañales y artículos similares, de cualquier materia. | D1578: =VLOOKUP(_xlfn.VALUETOTEXT($A1578),LIGIE_Jul_25!$A$2:$E$8125,4,FALSE) -> De pasta de papel, papel, guata de celulosa o napa de fibras de celulosa. | E1578: =_xlfn.IFNA(VLOOKUP(_xlfn.VALUETOTEXT($A1578),LIGIE_Iniciativa_Dec!$A$2:$E$1464,4,FALSE),"---") -> --- | F1578: =_xlfn.IFNA(VLOOKUP(_xlfn.VALUETOTEXT($A1578),LIGIE_Iniciativa_Dec!$A$2:$E$1464,4,FALSE),"---") -> ---
A1579: 96190002 | B1579: =LEFT(A1579,6) -> 961900 | C1579: =VLOOKUP(_xlfn.VALUETOTEXT($A1579),LIGIE_Jul_25!$A$2:$E$8125,3,FALSE) -> Mercancías y productos diversos. Manufacturas diversas. Compresas y tampones higiénicos, pañales y artículos similares, de cualquier materia. Compresas y tampones higiénicos, pañales y artículos similares, de cualquier materia. | D1579: =VLOOKUP(_xlfn.VALUETOTEXT($A1579),LIGIE_Jul_25!$A$2:$E$8125,4,FALSE) -> De guata de materia textil. | E1579: =_xlfn.IFNA(VLOOKUP(_xlfn.VALUETOTEXT($A1579),LIGIE_Iniciativa_Dec!$A$2:$E$1464,4,FALSE),"---") -> --- | F1579: =_xlfn.IFNA(VLOOKUP(_xlfn.VALUETOTEXT($A1579),LIGIE_Iniciativa_Dec!$A$2:$E$1464,4,FALSE),"---") -> ---
A1580: 96190003 | B1580: =LEFT(A1580,6) -> 961900 | C1580: =VLOOKUP(_xlfn.VALUETOTEXT($A1580),LIGIE_Jul_25!$A$2:$E$8125,3,FALSE) -> Mercancías y productos diversos. Manufacturas diversas. Compresas y tampones higiénicos, pañales y artículos similares, de cualquier materia. Compresas y tampones higiénicos, pañales y artículos similares, de cualquier materia. | D1580: =VLOOKUP(_xlfn.VALUETOTEXT($A1580),LIGIE_Jul_25!$A$2:$E$8125,4,FALSE) -> Pañales y articulos similares, de otras materias textiles, excepto lo comprendido en la fracción arancelaria 9619.00.02. | E1580: =_xlfn.IFNA(VLOOKUP(_xlfn.VALUETOTEXT($A1580),LIGIE_Iniciativa_Dec!$A$2:$E$1464,4,FALSE),"---") -> --- | F1580: =_xlfn.IFNA(VLOOKUP(_xlfn.VALUETOTEXT($A1580),LIGIE_Iniciativa_Dec!$A$2:$E$1464,4,FALSE),"---") -> ---

Sheet LIGIE_Iniciativa_Dec
A1: CÓDIGO | B1: DESCRIPCIÓN | C1: UNIDAD | D1: CUOTA_INICIATIVA | E1: CUOTA_DICTAMEN
A2: 33030001 | B2: Aguas de tocador. | C2: L | D2: 35 | E2: 25
A3: 33030099 | B3: Los demás. | C3: L | D3: 35 | E3: 25
A4: 33041001 | B4: Preparaciones para el maquillaje de los labios. | C4: Kg | D4: 50 | E4: 36
A5: 33042001 | B5: Preparaciones para el maquillaje de los ojos. | C5: Kg | D5: 35 | E5: 25
A6: 33043001 | B6: Preparaciones para manicuras o pedicuros. | C6: Kg | D6: 35 | E6: 25
A7: 33049101 | B7: Polvos, incluidos los compactos. | C7: Kg | D7: 35 | E7: 25
A8: 33049901 | B8: Leches cutáneas. | C8: Kg | D8: 35 | E8: 25
A9: 33049999 | B9: Las demás. | C9: Kg | D9: 35 | E9: 25
A10: 33051001 | B10: Champúes. | C10: Kg | D10: 35 | E10: 25
A11: 33052001 | B11: Preparaciones para ondulación o desrizado permanentes | C11: Kg | D11: 35 | E11: 25
A12: 33053001 | B12: Lacas para el cabello | C12: Kg | D12: 35 | E12: 25
A13: 33059099 | B13: Las demás | C13: Kg | D13: 35 | E13: 25
... A108: 40112006 | B108: Con diámetro interior inferior o igual a 44.45 cm. | C108: Pza | D108: 35 | E108: 35
A109: 40117003 | B109: De diámetro interior superior a 35 cm | C109: Pza | D109: --- | E109: 35
A110: 40117099 | B110: Los demás | C110: Pza | D110: --- | E110: 35
A111: 40169304 | B111: Juntas o empaquetaduras | C111: Kg | D111: 35 | E111: 25
A112: 42010001 | B112: Artículos de talabartería o para todos los animales (incluidos los tiros, traíllas rodilleras, bozales, sudaderos, alforjas abrigos para perros y artículos similares), de cualquier materia | C112: Pza | D112: 35 | E112: 25
A113: 42021101 | B113: Con la superficie Ex.terior de cuero natural o cuero regenerado | C113: Pza | D113: 35 | E113: 25
A114: 42021203 | B114: Con la superficie Ex.terior de plástico o materia tEx.til | C114: Pza | D114: 35 | E114: 25
A115: 42021999 | B115: Los demá s | C115: Pza | D115: 35 | E115: 25
A116: 42022101 | B116: Con la superficie Ex.terior de cuero natural o cuero regenerado | C116: Pza | D116: 35 | E116: 25
A117: 42022203 | B117: Con la superficie Ex.terior de hojas de plástico o materia tEx.til | C117: Pza | D117: 35 | E117: 25
A118: 42022999 | B118: Los demás | C118: Pza | D118: 35 | E118: 25
A119: 42023101 | B119: Con la superficie Ex.terior de cuero natural o cuero regenerado | C119: Pza | D119: 35 | E119: 25
A120: 42023203 | B120: Con la superficie Ex.terior de hojas de plástico o materia tEx.til | C120: Pza | D120: 35 | E120: 25
A121: 42023999 | B121: Los demás | C121: Pza | D121: 35 | E121: 25
A122: 42029101 | B122: Con la superficie Ex.terior de cuero natural o cuero regenerado. | C122: Pza | D122: 35 | E122: 25
... A136: 48044201 | B136: Blanqueados uniformemente en la masa y con un contenido de fibras de madera obtenidas por procedimiento químico superior al 95% en peso del contenido total de fibra. | C136: Kg | D136: 35 | E136: 35
A137: 48052402 | B137: De peso inferior o igual a 150 g/m2. " | C137: Kg | D137: --- | E137: 35
A138: 48052502 | B138: De peso superior a 150 g/m2. | C138: Kg | D138: 35 | E138: 35
A139: 48101307 | B139: En bobinas (rollos). | C139: Kg | D139: 35 | E139: 25
A140: 48102999 | B140: Los demás. | C140: Kg | D140: 35 | E140: 25
A141: 48103201 | B141: Blanqueados uniformemente en la masa y con un contenido de fibras de madera obtenidas por procedimiento químico superior al 95% en peso del contenido total de fibra, de peso superior a 150 g/m*”. | C141: Kg | D141: 35 | E141: 25
A142: 48103999 | B142: Los demás. | C142: Kg | D142: 35 | E142: 25
A143: 48109201 | B143: Multicapas | C143: Kg | D143: 35 | E143: 25
A144: 48109999 | B144: Los demás | C144: Kg | D144: 35 | E144: 25
A145: 48114102 | B145: En tiras o en bobinas (rollos) | C145: Kg | D145: 35 | E145: 25
A146: 48114901 | B146: En tiras o en bobinas (rollos) | C146: Kg | D146: --- | E146: 35
A147: 48142001 | B147: Papel para decorar y revestimientos similares de paredes, constituidos por papel recubierto o revestido, en la cara vista, con una capa de plástico graneada, gofrada, coloreada impresa con motivos o decorada de otro modo | C147: Kg | D147: 35 | E147: 25
...
